Traceback (most recent call last):
  File "/usr/share/miniconda/envs/test/lib/python3.8/site-packages/jupyter_cache/executors/utils.py", line 51, in single_nb_execution
    executenb(
  File "/usr/share/miniconda/envs/test/lib/python3.8/site-packages/nbclient/client.py", line 1085, in execute
    return NotebookClient(nb=nb, resources=resources, km=km, **kwargs).execute()
  File "/usr/share/miniconda/envs/test/lib/python3.8/site-packages/nbclient/util.py", line 84, in wrapped
    return just_run(coro(*args, **kwargs))
  File "/usr/share/miniconda/envs/test/lib/python3.8/site-packages/nbclient/util.py", line 62, in just_run
    return loop.run_until_complete(coro)
  File "/usr/share/miniconda/envs/test/lib/python3.8/asyncio/base_events.py", line 616, in run_until_complete
    return future.result()
  File "/usr/share/miniconda/envs/test/lib/python3.8/site-packages/nbclient/client.py", line 551, in async_execute
    await self.async_execute_cell(
  File "/usr/share/miniconda/envs/test/lib/python3.8/site-packages/nbclient/client.py", line 846, in async_execute_cell
    self._check_raise_for_error(cell, exec_reply)
  File "/usr/share/miniconda/envs/test/lib/python3.8/site-packages/nbclient/client.py", line 748, in _check_raise_for_error
    raise CellExecutionError.from_cell_and_msg(cell, exec_reply_content)
nbclient.exceptions.CellExecutionError: An error occurred while executing the following cell:
------------------
from pathlib import Path

import numpy as np
from matplotlib import pyplot as plt

from astropy.nddata import CCDData
from astropy.nddata.utils import block_replicate
from astropy import units as u
import ccdproc as ccdp
from photutils import detect_sources

from convenience_functions import show_image, display_cosmic_rays
------------------

[0;31m---------------------------------------------------------------------------[0m
[0;31mImportError[0m                               Traceback (most recent call last)
Input [0;32mIn [1][0m, in [0;36m<module>[0;34m[0m
[1;32m      4[0m [38;5;28;01mfrom[39;00m [38;5;21;01mmatplotlib[39;00m [38;5;28;01mimport[39;00m pyplot [38;5;28;01mas[39;00m plt
[1;32m      6[0m [38;5;28;01mfrom[39;00m [38;5;21;01mastropy[39;00m[38;5;21;01m.[39;00m[38;5;21;01mnddata[39;00m [38;5;28;01mimport[39;00m CCDData
[0;32m----> 7[0m [38;5;28;01mfrom[39;00m [38;5;21;01mastropy[39;00m[38;5;21;01m.[39;00m[38;5;21;01mnddata[39;00m[38;5;21;01m.[39;00m[38;5;21;01mutils[39;00m [38;5;28;01mimport[39;00m block_replicate
[1;32m      8[0m [38;5;28;01mfrom[39;00m [38;5;21;01mastropy[39;00m [38;5;28;01mimport[39;00m units [38;5;28;01mas[39;00m u
[1;32m      9[0m [38;5;28;01mimport[39;00m [38;5;21;01mccdproc[39;00m [38;5;28;01mas[39;00m [38;5;21;01mccdp[39;00m

[0;31mImportError[0m: cannot import name 'block_replicate' from 'astropy.nddata.utils' (/usr/share/miniconda/envs/test/lib/python3.8/site-packages/astropy/nddata/utils.py)
ImportError: cannot import name 'block_replicate' from 'astropy.nddata.utils' (/usr/share/miniconda/envs/test/lib/python3.8/site-packages/astropy/nddata/utils.py)

